-------------------- Log Start | Sat Nov 23 07:20:48 2024 --------------------
platform: Linux-6.1.21-v8+-aarch64-with-glibc2.31
data_path: /home/pi/Ender5_data
is_default_data_path: False
config_file: /home/pi/Ender5_data/config/moonraker.conf
backup_config: None
startup_warnings: []
verbose: False
debug: False
asyncio_debug: False
is_backup_config: False
is_python_package: False
instance_uuid: 7b1425501a69432ca838d218c97a15b3
unix_socket_path: /home/pi/Ender5_data/comms/moonraker.sock
software_version: v0.9.3-3-gccfe32f
git_branch: master
git_remote: origin
git_repo_url: https://github.com/Arksine/moonraker.git
modified_files: []
unofficial_components: []
log_file: /home/pi/Ender5_data/logs/moonraker.log
python_version: 3.9.2 (default, Mar 12 2021, 04:06:34)  [GCC 10.2.1 20210110]
launch_args: /home/pi/moonraker-env/bin/python /home/pi/moonraker/moonraker/moonraker.py -d /home/pi/Ender5_data
msgspec_enabled: False
uvloop_enabled: False

#################### Moonraker Configuration ####################

[server]
host = 0.0.0.0
port = 7126
klippy_uds_address = /home/pi/Ender5_data/comms/klippy.sock

[file_manager]
enable_object_processing = True

[authorization]
trusted_clients = 
	127.0.0.1
	10.0.0.0/8
	127.0.0.0/8
	169.254.0.0/16
	172.16.0.0/12
	192.168.0.0/16
	FE80::/10
	::1/128
	192.168.1.224
cors_domains = 
	*.lan
	*.local
	*://localhost
	*://localhost:*
	*://my.mainsail.xyz
	*://app.fluidd.xyz
	*://Ender5
	*://Ender5.local
	*://192.168.1.224

[octoprint_compat]

[history]

[update_manager]
refresh_interval = 168

[update_manager mainsail]
type = web
repo = mainsail-crew/mainsail
path = ~/mainsail

[update_manager KlipperScreen]
type = git_repo
path = ~/KlipperScreen
origin = https://github.com/jordanruthe/KlipperScreen.git
env = ~/.KlipperScreen-env/bin/python
requirements = scripts/KlipperScreen-requirements.txt
install_script = scripts/KlipperScreen-install.sh
managed_services = KlipperScreen

[update_manager crowsnest]
type = git_repo
path = ~/crowsnest
origin = https://github.com/mainsail-crew/crowsnest.git
install_script = tools/install.sh

[update_manager client moonraker-telegram-bot]
type = git_repo
path = ~/moonraker-telegram-bot
origin = https://github.com/nlef/moonraker-telegram-bot.git
env = ~/moonraker-telegram-bot-env/bin/python
requirements = scripts/requirements.txt
install_script = scripts/install.sh

[update_manager klipper-backup]
type = git_repo
path = ~/klipper-backup
origin = https://github.com/Staubgeborener/klipper-backup.git
managed_services = moonraker
primary_branch = main

[power light_strip]
type = gpio
pin = gpiochip0/gpio16
initial_state = off

#################################################################
All Configuration Files:
/home/pi/Ender5_data/config/moonraker.conf
#################################################################
Loading Sqlite database provider. Sqlite Version: 3.34.1
Unsafe Shutdown Count: 62

System Info:

***python***
  version: (3, 9, 2, 'final', 0)
  version_string: 3.9.2 (default, Mar 12 2021, 04:06:34)  [GCC 10.2.1 20210110]

***cpu_info***
  cpu_count: 4
  bits: 32bit
  processor: aarch64
  cpu_desc: 
  serial_number: 100000004453ee49
  hardware_desc: BCM2835
  model: Raspberry Pi 4 Model B Rev 1.4
  total_memory: 3705528
  memory_units: kB

***sd_info***
  manufacturer_id: 6f
  manufacturer: Unknown
  oem_id: 0303
  product_name: CBADS
  product_revision: 1.0
  serial_number: aa0005c6
  manufacturer_date: 10/2022
  capacity: 29.1 GiB
  total_bytes: 31275876352

***distribution***
  name: Raspbian GNU/Linux 11 (bullseye)
  id: raspbian
  version: 11
  version_parts: {'major': '11', 'minor': '', 'build_number': ''}
  like: debian
  codename: bullseye
  release_info: {}
  kernel_version: 6.1.21-v8+

***virtualization***
  virt_type: none
  virt_identifier: none

***network***

***canbus***

***Allowed Services***
  klipper_mcu
  webcamd
  MoonCord
  KlipperScreen
  moonraker-telegram-bot
  moonraker-obico
  sonar
  crowsnest
  octoeverywhere
Found libcamera Python module, version: v0.0.5+83-bde9b04f

Systemd unit moonraker-Ender5.service:
unit_name: moonraker-Ender5.service
is_default: False
manager: systemd
Properties:
**Requires=['sysinit.target', 'network-online.target', 'system.slice', '-.mount']
**After=['sysinit.target', 'basic.target', 'network-online.target', 'systemd-journald.socket', 'system.slice', '-.mount']
**SupplementaryGroups=['moonraker-admin']
**EnvironmentFiles=/home/pi/Ender5_data/systemd/moonraker.env
**ExecStart=/home/pi/moonraker-env/bin/python $MOONRAKER_ARGS
**WorkingDirectory=/home/pi/moonraker
**FragmentPath=/etc/systemd/system/moonraker-Ender5.service
**Description=API Server for Klipper SV1 Ender5
**User=pi

Systemd unit klipper-Ender5.service:
unit_name: klipper-Ender5.service
is_default: False
manager: systemd
Properties:
**Requires=['-.mount', 'system.slice', 'sysinit.target']
**After=['sysinit.target', 'system.slice', 'network-online.target', 'basic.target', '-.mount', 'systemd-journald.socket']
**SupplementaryGroups=[]
**EnvironmentFiles=/home/pi/Ender5_data/systemd/klipper.env
**ExecStart=/home/pi/klippy-env/bin/python $KLIPPER_ARGS
**WorkingDirectory=/home/pi/klipper
**FragmentPath=/etc/systemd/system/klipper-Ender5.service
**Description=Klipper 3D Printer Firmware SV1
**User=pi
Multiple instances of Moonraker have the update manager enabled.
moonraker-Ender3:f3b73e6f93a14a268ea6fcddf0c3f001:836
moonraker-Ender5:7b1425501a69432ca838d218c97a15b3:844
Git Repo moonraker: No warnings detected
Git Repo klipper: Warnings detected:
  Repo has untracked source files: ['klippy/extras/gcode_shell_command.py']
Git Repo KlipperScreen: No warnings detected
Git Repo crowsnest: No warnings detected
Git Repo moonraker-telegram-bot: No warnings detected
Klipper Version: v0.12.0-378-gd6494ffed-dirty
Git Repo klipper-backup: No warnings detected
2024-11-23 01:20:48,847 [ioloop.py:_run_callback()] - Exception in callback functools.partial(<function _HTTPConnection.__init__.<locals>.<lambda> at 0xf1f69460>, <Task finished name='Task-2161031' coro=<_HTTPConnection.run() done, defined at /home/pi/moonraker-env/lib/python3.9/site-packages/tornado/simple_httpclient.py:290> exception=gaierror(-3, 'Temporary failure in name resolution')>)
Traceback (most recent call last):
  File "/home/pi/moonraker-env/lib/python3.9/site-packages/tornado/ioloop.py", line 750, in _run_callback
    ret = callback()
  File "/home/pi/moonraker-env/lib/python3.9/site-packages/tornado/simple_httpclient.py", line 287, in <lambda>
    gen.convert_yielded(self.run()), lambda f: f.result()
  File "/home/pi/moonraker-env/lib/python3.9/site-packages/tornado/simple_httpclient.py", line 340, in run
    stream = await self.tcp_client.connect(
  File "/home/pi/moonraker-env/lib/python3.9/site-packages/tornado/tcpclient.py", line 269, in connect
    addrinfo = await self.resolver.resolve(host, port, af)
  File "/home/pi/moonraker-env/lib/python3.9/site-packages/tornado/netutil.py", line 433, in resolve
    for fam, _, _, _, address in await asyncio.get_running_loop().getaddrinfo(
  File "/usr/lib/python3.9/asyncio/base_events.py", line 856, in getaddrinfo
    return await self.run_in_executor(
  File "/usr/lib/python3.9/concurrent/futures/thread.py", line 52, in run
    result = self.fn(*self.args, **self.kwargs)
  File "/usr/lib/python3.9/socket.py", line 953, in getaddrinfo
    for res in _socket.getaddrinfo(host, port, family, type, proto, flags):
socket.gaierror: [Errno -3] Temporary failure in name resolution
2024-11-23 01:20:51,561 [announcements.py:_fetch_moonlight()] - Failed to update subscription 'moonraker': Timeout while connecting
2024-11-23 01:20:51,919 [ioloop.py:_run_callback()] - Exception in callback functools.partial(<function _HTTPConnection.__init__.<locals>.<lambda> at 0xf1f47fa0>, <Task finished name='Task-2161540' coro=<_HTTPConnection.run() done, defined at /home/pi/moonraker-env/lib/python3.9/site-packages/tornado/simple_httpclient.py:290> exception=gaierror(-3, 'Temporary failure in name resolution')>)
Traceback (most recent call last):
  File "/home/pi/moonraker-env/lib/python3.9/site-packages/tornado/ioloop.py", line 750, in _run_callback
    ret = callback()
  File "/home/pi/moonraker-env/lib/python3.9/site-packages/tornado/simple_httpclient.py", line 287, in <lambda>
    gen.convert_yielded(self.run()), lambda f: f.result()
  File "/home/pi/moonraker-env/lib/python3.9/site-packages/tornado/simple_httpclient.py", line 340, in run
    stream = await self.tcp_client.connect(
  File "/home/pi/moonraker-env/lib/python3.9/site-packages/tornado/tcpclient.py", line 269, in connect
    addrinfo = await self.resolver.resolve(host, port, af)
  File "/home/pi/moonraker-env/lib/python3.9/site-packages/tornado/netutil.py", line 433, in resolve
    for fam, _, _, _, address in await asyncio.get_running_loop().getaddrinfo(
  File "/usr/lib/python3.9/asyncio/base_events.py", line 856, in getaddrinfo
    return await self.run_in_executor(
  File "/usr/lib/python3.9/concurrent/futures/thread.py", line 52, in run
    result = self.fn(*self.args, **self.kwargs)
  File "/usr/lib/python3.9/socket.py", line 953, in getaddrinfo
    for res in _socket.getaddrinfo(host, port, family, type, proto, flags):
socket.gaierror: [Errno -3] Temporary failure in name resolution
2024-11-23 01:20:58,067 [ioloop.py:_run_callback()] - Exception in callback functools.partial(<function _HTTPConnection.__init__.<locals>.<lambda> at 0xf1f47658>, <Task finished name='Task-2162017' coro=<_HTTPConnection.run() done, defined at /home/pi/moonraker-env/lib/python3.9/site-packages/tornado/simple_httpclient.py:290> exception=gaierror(-3, 'Temporary failure in name resolution')>)
Traceback (most recent call last):
  File "/home/pi/moonraker-env/lib/python3.9/site-packages/tornado/ioloop.py", line 750, in _run_callback
    ret = callback()
  File "/home/pi/moonraker-env/lib/python3.9/site-packages/tornado/simple_httpclient.py", line 287, in <lambda>
    gen.convert_yielded(self.run()), lambda f: f.result()
  File "/home/pi/moonraker-env/lib/python3.9/site-packages/tornado/simple_httpclient.py", line 340, in run
    stream = await self.tcp_client.connect(
  File "/home/pi/moonraker-env/lib/python3.9/site-packages/tornado/tcpclient.py", line 269, in connect
    addrinfo = await self.resolver.resolve(host, port, af)
  File "/home/pi/moonraker-env/lib/python3.9/site-packages/tornado/netutil.py", line 433, in resolve
    for fam, _, _, _, address in await asyncio.get_running_loop().getaddrinfo(
  File "/usr/lib/python3.9/asyncio/base_events.py", line 856, in getaddrinfo
    return await self.run_in_executor(
  File "/usr/lib/python3.9/concurrent/futures/thread.py", line 52, in run
    result = self.fn(*self.args, **self.kwargs)
  File "/usr/lib/python3.9/socket.py", line 953, in getaddrinfo
    for res in _socket.getaddrinfo(host, port, family, type, proto, flags):
socket.gaierror: [Errno -3] Temporary failure in name resolution
2024-11-23 01:21:04,210 [ioloop.py:_run_callback()] - Exception in callback functools.partial(<function _HTTPConnection.__init__.<locals>.<lambda> at 0xf1f47a00>, <Task finished name='Task-2162541' coro=<_HTTPConnection.run() done, defined at /home/pi/moonraker-env/lib/python3.9/site-packages/tornado/simple_httpclient.py:290> exception=gaierror(-3, 'Temporary failure in name resolution')>)
Traceback (most recent call last):
  File "/home/pi/moonraker-env/lib/python3.9/site-packages/tornado/ioloop.py", line 750, in _run_callback
    ret = callback()
  File "/home/pi/moonraker-env/lib/python3.9/site-packages/tornado/simple_httpclient.py", line 287, in <lambda>
    gen.convert_yielded(self.run()), lambda f: f.result()
  File "/home/pi/moonraker-env/lib/python3.9/site-packages/tornado/simple_httpclient.py", line 340, in run
    stream = await self.tcp_client.connect(
  File "/home/pi/moonraker-env/lib/python3.9/site-packages/tornado/tcpclient.py", line 269, in connect
    addrinfo = await self.resolver.resolve(host, port, af)
  File "/home/pi/moonraker-env/lib/python3.9/site-packages/tornado/netutil.py", line 433, in resolve
    for fam, _, _, _, address in await asyncio.get_running_loop().getaddrinfo(
  File "/usr/lib/python3.9/asyncio/base_events.py", line 856, in getaddrinfo
    return await self.run_in_executor(
  File "/usr/lib/python3.9/concurrent/futures/thread.py", line 52, in run
    result = self.fn(*self.args, **self.kwargs)
  File "/usr/lib/python3.9/socket.py", line 953, in getaddrinfo
    for res in _socket.getaddrinfo(host, port, family, type, proto, flags):
socket.gaierror: [Errno -3] Temporary failure in name resolution
2024-11-23 01:21:10,351 [ioloop.py:_run_callback()] - Exception in callback functools.partial(<function _HTTPConnection.__init__.<locals>.<lambda> at 0xf1f7ca00>, <Task finished name='Task-2163072' coro=<_HTTPConnection.run() done, defined at /home/pi/moonraker-env/lib/python3.9/site-packages/tornado/simple_httpclient.py:290> exception=gaierror(-3, 'Temporary failure in name resolution')>)
Traceback (most recent call last):
  File "/home/pi/moonraker-env/lib/python3.9/site-packages/tornado/ioloop.py", line 750, in _run_callback
    ret = callback()
  File "/home/pi/moonraker-env/lib/python3.9/site-packages/tornado/simple_httpclient.py", line 287, in <lambda>
    gen.convert_yielded(self.run()), lambda f: f.result()
  File "/home/pi/moonraker-env/lib/python3.9/site-packages/tornado/simple_httpclient.py", line 340, in run
    stream = await self.tcp_client.connect(
  File "/home/pi/moonraker-env/lib/python3.9/site-packages/tornado/tcpclient.py", line 269, in connect
    addrinfo = await self.resolver.resolve(host, port, af)
  File "/home/pi/moonraker-env/lib/python3.9/site-packages/tornado/netutil.py", line 433, in resolve
    for fam, _, _, _, address in await asyncio.get_running_loop().getaddrinfo(
  File "/usr/lib/python3.9/asyncio/base_events.py", line 856, in getaddrinfo
    return await self.run_in_executor(
  File "/usr/lib/python3.9/concurrent/futures/thread.py", line 52, in run
    result = self.fn(*self.args, **self.kwargs)
  File "/usr/lib/python3.9/socket.py", line 953, in getaddrinfo
    for res in _socket.getaddrinfo(host, port, family, type, proto, flags):
socket.gaierror: [Errno -3] Temporary failure in name resolution
2024-11-23 01:21:13,423 [ioloop.py:_run_callback()] - Exception in callback functools.partial(<function _HTTPConnection.__init__.<locals>.<lambda> at 0xf15b7220>, <Task finished name='Task-2163500' coro=<_HTTPConnection.run() done, defined at /home/pi/moonraker-env/lib/python3.9/site-packages/tornado/simple_httpclient.py:290> exception=gaierror(-3, 'Temporary failure in name resolution')>)
Traceback (most recent call last):
  File "/home/pi/moonraker-env/lib/python3.9/site-packages/tornado/ioloop.py", line 750, in _run_callback
    ret = callback()
  File "/home/pi/moonraker-env/lib/python3.9/site-packages/tornado/simple_httpclient.py", line 287, in <lambda>
    gen.convert_yielded(self.run()), lambda f: f.result()
  File "/home/pi/moonraker-env/lib/python3.9/site-packages/tornado/simple_httpclient.py", line 340, in run
    stream = await self.tcp_client.connect(
  File "/home/pi/moonraker-env/lib/python3.9/site-packages/tornado/tcpclient.py", line 269, in connect
    addrinfo = await self.resolver.resolve(host, port, af)
  File "/home/pi/moonraker-env/lib/python3.9/site-packages/tornado/netutil.py", line 433, in resolve
    for fam, _, _, _, address in await asyncio.get_running_loop().getaddrinfo(
  File "/usr/lib/python3.9/asyncio/base_events.py", line 856, in getaddrinfo
    return await self.run_in_executor(
  File "/usr/lib/python3.9/concurrent/futures/thread.py", line 52, in run
    result = self.fn(*self.args, **self.kwargs)
  File "/usr/lib/python3.9/socket.py", line 953, in getaddrinfo
    for res in _socket.getaddrinfo(host, port, family, type, proto, flags):
socket.gaierror: [Errno -3] Temporary failure in name resolution
2024-11-23 01:21:18,572 [announcements.py:_fetch_moonlight()] - Failed to update subscription 'klipper': Timeout while connecting
2024-11-23 01:21:19,567 [ioloop.py:_run_callback()] - Exception in callback functools.partial(<function _HTTPConnection.__init__.<locals>.<lambda> at 0xf1f47da8>, <Task finished name='Task-2164021' coro=<_HTTPConnection.run() done, defined at /home/pi/moonraker-env/lib/python3.9/site-packages/tornado/simple_httpclient.py:290> exception=gaierror(-3, 'Temporary failure in name resolution')>)
Traceback (most recent call last):
  File "/home/pi/moonraker-env/lib/python3.9/site-packages/tornado/ioloop.py", line 750, in _run_callback
    ret = callback()
  File "/home/pi/moonraker-env/lib/python3.9/site-packages/tornado/simple_httpclient.py", line 287, in <lambda>
    gen.convert_yielded(self.run()), lambda f: f.result()
  File "/home/pi/moonraker-env/lib/python3.9/site-packages/tornado/simple_httpclient.py", line 340, in run
    stream = await self.tcp_client.connect(
  File "/home/pi/moonraker-env/lib/python3.9/site-packages/tornado/tcpclient.py", line 269, in connect
    addrinfo = await self.resolver.resolve(host, port, af)
  File "/home/pi/moonraker-env/lib/python3.9/site-packages/tornado/netutil.py", line 433, in resolve
    for fam, _, _, _, address in await asyncio.get_running_loop().getaddrinfo(
  File "/usr/lib/python3.9/asyncio/base_events.py", line 856, in getaddrinfo
    return await self.run_in_executor(
  File "/usr/lib/python3.9/concurrent/futures/thread.py", line 52, in run
    result = self.fn(*self.args, **self.kwargs)
  File "/usr/lib/python3.9/socket.py", line 953, in getaddrinfo
    for res in _socket.getaddrinfo(host, port, family, type, proto, flags):
socket.gaierror: [Errno -3] Temporary failure in name resolution
2024-11-23 01:21:25,711 [ioloop.py:_run_callback()] - Exception in callback functools.partial(<function _HTTPConnection.__init__.<locals>.<lambda> at 0xf1f47cd0>, <Task finished name='Task-2164464' coro=<_HTTPConnection.run() done, defined at /home/pi/moonraker-env/lib/python3.9/site-packages/tornado/simple_httpclient.py:290> exception=gaierror(-3, 'Temporary failure in name resolution')>)
Traceback (most recent call last):
  File "/home/pi/moonraker-env/lib/python3.9/site-packages/tornado/ioloop.py", line 750, in _run_callback
    ret = callback()
  File "/home/pi/moonraker-env/lib/python3.9/site-packages/tornado/simple_httpclient.py", line 287, in <lambda>
    gen.convert_yielded(self.run()), lambda f: f.result()
  File "/home/pi/moonraker-env/lib/python3.9/site-packages/tornado/simple_httpclient.py", line 340, in run
    stream = await self.tcp_client.connect(
  File "/home/pi/moonraker-env/lib/python3.9/site-packages/tornado/tcpclient.py", line 269, in connect
    addrinfo = await self.resolver.resolve(host, port, af)
  File "/home/pi/moonraker-env/lib/python3.9/site-packages/tornado/netutil.py", line 433, in resolve
    for fam, _, _, _, address in await asyncio.get_running_loop().getaddrinfo(
  File "/usr/lib/python3.9/asyncio/base_events.py", line 856, in getaddrinfo
    return await self.run_in_executor(
  File "/usr/lib/python3.9/concurrent/futures/thread.py", line 52, in run
    result = self.fn(*self.args, **self.kwargs)
  File "/usr/lib/python3.9/socket.py", line 953, in getaddrinfo
    for res in _socket.getaddrinfo(host, port, family, type, proto, flags):
socket.gaierror: [Errno -3] Temporary failure in name resolution
2024-11-23 01:21:31,855 [ioloop.py:_run_callback()] - Exception in callback functools.partial(<function _HTTPConnection.__init__.<locals>.<lambda> at 0xf15beec8>, <Task finished name='Task-2164983' coro=<_HTTPConnection.run() done, defined at /home/pi/moonraker-env/lib/python3.9/site-packages/tornado/simple_httpclient.py:290> exception=gaierror(-3, 'Temporary failure in name resolution')>)
Traceback (most recent call last):
  File "/home/pi/moonraker-env/lib/python3.9/site-packages/tornado/ioloop.py", line 750, in _run_callback
    ret = callback()
  File "/home/pi/moonraker-env/lib/python3.9/site-packages/tornado/simple_httpclient.py", line 287, in <lambda>
    gen.convert_yielded(self.run()), lambda f: f.result()
  File "/home/pi/moonraker-env/lib/python3.9/site-packages/tornado/simple_httpclient.py", line 340, in run
    stream = await self.tcp_client.connect(
  File "/home/pi/moonraker-env/lib/python3.9/site-packages/tornado/tcpclient.py", line 269, in connect
    addrinfo = await self.resolver.resolve(host, port, af)
  File "/home/pi/moonraker-env/lib/python3.9/site-packages/tornado/netutil.py", line 433, in resolve
    for fam, _, _, _, address in await asyncio.get_running_loop().getaddrinfo(
  File "/usr/lib/python3.9/asyncio/base_events.py", line 856, in getaddrinfo
    return await self.run_in_executor(
  File "/usr/lib/python3.9/concurrent/futures/thread.py", line 52, in run
    result = self.fn(*self.args, **self.kwargs)
  File "/usr/lib/python3.9/socket.py", line 953, in getaddrinfo
    for res in _socket.getaddrinfo(host, port, family, type, proto, flags):
socket.gaierror: [Errno -3] Temporary failure in name resolution
2024-11-23 01:21:37,999 [ioloop.py:_run_callback()] - Exception in callback functools.partial(<function _HTTPConnection.__init__.<locals>.<lambda> at 0xf15bec40>, <Task finished name='Task-2165473' coro=<_HTTPConnection.run() done, defined at /home/pi/moonraker-env/lib/python3.9/site-packages/tornado/simple_httpclient.py:290> exception=gaierror(-3, 'Temporary failure in name resolution')>)
Traceback (most recent call last):
  File "/home/pi/moonraker-env/lib/python3.9/site-packages/tornado/ioloop.py", line 750, in _run_callback
    ret = callback()
  File "/home/pi/moonraker-env/lib/python3.9/site-packages/tornado/simple_httpclient.py", line 287, in <lambda>
    gen.convert_yielded(self.run()), lambda f: f.result()
  File "/home/pi/moonraker-env/lib/python3.9/site-packages/tornado/simple_httpclient.py", line 340, in run
    stream = await self.tcp_client.connect(
  File "/home/pi/moonraker-env/lib/python3.9/site-packages/tornado/tcpclient.py", line 269, in connect
    addrinfo = await self.resolver.resolve(host, port, af)
  File "/home/pi/moonraker-env/lib/python3.9/site-packages/tornado/netutil.py", line 433, in resolve
    for fam, _, _, _, address in await asyncio.get_running_loop().getaddrinfo(
  File "/usr/lib/python3.9/asyncio/base_events.py", line 856, in getaddrinfo
    return await self.run_in_executor(
  File "/usr/lib/python3.9/concurrent/futures/thread.py", line 52, in run
    result = self.fn(*self.args, **self.kwargs)
  File "/usr/lib/python3.9/socket.py", line 953, in getaddrinfo
    for res in _socket.getaddrinfo(host, port, family, type, proto, flags):
socket.gaierror: [Errno -3] Temporary failure in name resolution
2024-11-23 01:21:41,073 [ioloop.py:_run_callback()] - Exception in callback functools.partial(<function _HTTPConnection.__init__.<locals>.<lambda> at 0xf1f476e8>, <Task finished name='Task-2165933' coro=<_HTTPConnection.run() done, defined at /home/pi/moonraker-env/lib/python3.9/site-packages/tornado/simple_httpclient.py:290> exception=gaierror(-3, 'Temporary failure in name resolution')>)
Traceback (most recent call last):
  File "/home/pi/moonraker-env/lib/python3.9/site-packages/tornado/ioloop.py", line 750, in _run_callback
    ret = callback()
  File "/home/pi/moonraker-env/lib/python3.9/site-packages/tornado/simple_httpclient.py", line 287, in <lambda>
    gen.convert_yielded(self.run()), lambda f: f.result()
  File "/home/pi/moonraker-env/lib/python3.9/site-packages/tornado/simple_httpclient.py", line 340, in run
    stream = await self.tcp_client.connect(
  File "/home/pi/moonraker-env/lib/python3.9/site-packages/tornado/tcpclient.py", line 269, in connect
    addrinfo = await self.resolver.resolve(host, port, af)
  File "/home/pi/moonraker-env/lib/python3.9/site-packages/tornado/netutil.py", line 433, in resolve
    for fam, _, _, _, address in await asyncio.get_running_loop().getaddrinfo(
  File "/usr/lib/python3.9/asyncio/base_events.py", line 856, in getaddrinfo
    return await self.run_in_executor(
  File "/usr/lib/python3.9/concurrent/futures/thread.py", line 52, in run
    result = self.fn(*self.args, **self.kwargs)
  File "/usr/lib/python3.9/socket.py", line 953, in getaddrinfo
    for res in _socket.getaddrinfo(host, port, family, type, proto, flags):
socket.gaierror: [Errno -3] Temporary failure in name resolution
2024-11-23 01:21:45,586 [announcements.py:_fetch_moonlight()] - Failed to update subscription 'moonraker-telegram-bot': Timeout while connecting
2024-11-23 01:21:47,215 [ioloop.py:_run_callback()] - Exception in callback functools.partial(<function _HTTPConnection.__init__.<locals>.<lambda> at 0xf15b7220>, <Task finished name='Task-2166462' coro=<_HTTPConnection.run() done, defined at /home/pi/moonraker-env/lib/python3.9/site-packages/tornado/simple_httpclient.py:290> exception=gaierror(-3, 'Temporary failure in name resolution')>)
Traceback (most recent call last):
  File "/home/pi/moonraker-env/lib/python3.9/site-packages/tornado/ioloop.py", line 750, in _run_callback
    ret = callback()
  File "/home/pi/moonraker-env/lib/python3.9/site-packages/tornado/simple_httpclient.py", line 287, in <lambda>
    gen.convert_yielded(self.run()), lambda f: f.result()
  File "/home/pi/moonraker-env/lib/python3.9/site-packages/tornado/simple_httpclient.py", line 340, in run
    stream = await self.tcp_client.connect(
  File "/home/pi/moonraker-env/lib/python3.9/site-packages/tornado/tcpclient.py", line 269, in connect
    addrinfo = await self.resolver.resolve(host, port, af)
  File "/home/pi/moonraker-env/lib/python3.9/site-packages/tornado/netutil.py", line 433, in resolve
    for fam, _, _, _, address in await asyncio.get_running_loop().getaddrinfo(
  File "/usr/lib/python3.9/asyncio/base_events.py", line 856, in getaddrinfo
    return await self.run_in_executor(
  File "/usr/lib/python3.9/concurrent/futures/thread.py", line 52, in run
    result = self.fn(*self.args, **self.kwargs)
  File "/usr/lib/python3.9/socket.py", line 953, in getaddrinfo
    for res in _socket.getaddrinfo(host, port, family, type, proto, flags):
socket.gaierror: [Errno -3] Temporary failure in name resolution
2024-11-23 01:21:53,359 [ioloop.py:_run_callback()] - Exception in callback functools.partial(<function _HTTPConnection.__init__.<locals>.<lambda> at 0xf15befa0>, <Task finished name='Task-2166926' coro=<_HTTPConnection.run() done, defined at /home/pi/moonraker-env/lib/python3.9/site-packages/tornado/simple_httpclient.py:290> exception=gaierror(-3, 'Temporary failure in name resolution')>)
Traceback (most recent call last):
  File "/home/pi/moonraker-env/lib/python3.9/site-packages/tornado/ioloop.py", line 750, in _run_callback
    ret = callback()
  File "/home/pi/moonraker-env/lib/python3.9/site-packages/tornado/simple_httpclient.py", line 287, in <lambda>
    gen.convert_yielded(self.run()), lambda f: f.result()
  File "/home/pi/moonraker-env/lib/python3.9/site-packages/tornado/simple_httpclient.py", line 340, in run
    stream = await self.tcp_client.connect(
  File "/home/pi/moonraker-env/lib/python3.9/site-packages/tornado/tcpclient.py", line 269, in connect
    addrinfo = await self.resolver.resolve(host, port, af)
  File "/home/pi/moonraker-env/lib/python3.9/site-packages/tornado/netutil.py", line 433, in resolve
    for fam, _, _, _, address in await asyncio.get_running_loop().getaddrinfo(
  File "/usr/lib/python3.9/asyncio/base_events.py", line 856, in getaddrinfo
    return await self.run_in_executor(
  File "/usr/lib/python3.9/concurrent/futures/thread.py", line 52, in run
    result = self.fn(*self.args, **self.kwargs)
  File "/usr/lib/python3.9/socket.py", line 953, in getaddrinfo
    for res in _socket.getaddrinfo(host, port, family, type, proto, flags):
socket.gaierror: [Errno -3] Temporary failure in name resolution
2024-11-23 01:21:59,504 [ioloop.py:_run_callback()] - Exception in callback functools.partial(<function _HTTPConnection.__init__.<locals>.<lambda> at 0xf1f479b8>, <Task finished name='Task-2167464' coro=<_HTTPConnection.run() done, defined at /home/pi/moonraker-env/lib/python3.9/site-packages/tornado/simple_httpclient.py:290> exception=gaierror(-3, 'Temporary failure in name resolution')>)
Traceback (most recent call last):
  File "/home/pi/moonraker-env/lib/python3.9/site-packages/tornado/ioloop.py", line 750, in _run_callback
    ret = callback()
  File "/home/pi/moonraker-env/lib/python3.9/site-packages/tornado/simple_httpclient.py", line 287, in <lambda>
    gen.convert_yielded(self.run()), lambda f: f.result()
  File "/home/pi/moonraker-env/lib/python3.9/site-packages/tornado/simple_httpclient.py", line 340, in run
    stream = await self.tcp_client.connect(
  File "/home/pi/moonraker-env/lib/python3.9/site-packages/tornado/tcpclient.py", line 269, in connect
    addrinfo = await self.resolver.resolve(host, port, af)
  File "/home/pi/moonraker-env/lib/python3.9/site-packages/tornado/netutil.py", line 433, in resolve
    for fam, _, _, _, address in await asyncio.get_running_loop().getaddrinfo(
  File "/usr/lib/python3.9/asyncio/base_events.py", line 856, in getaddrinfo
    return await self.run_in_executor(
  File "/usr/lib/python3.9/concurrent/futures/thread.py", line 52, in run
    result = self.fn(*self.args, **self.kwargs)
  File "/usr/lib/python3.9/socket.py", line 953, in getaddrinfo
    for res in _socket.getaddrinfo(host, port, family, type, proto, flags):
socket.gaierror: [Errno -3] Temporary failure in name resolution
2024-11-23 01:22:02,574 [ioloop.py:_run_callback()] - Exception in callback functools.partial(<function _HTTPConnection.__init__.<locals>.<lambda> at 0xf15bec88>, <Task finished name='Task-2167950' coro=<_HTTPConnection.run() done, defined at /home/pi/moonraker-env/lib/python3.9/site-packages/tornado/simple_httpclient.py:290> exception=gaierror(-3, 'Temporary failure in name resolution')>)
Traceback (most recent call last):
  File "/home/pi/moonraker-env/lib/python3.9/site-packages/tornado/ioloop.py", line 750, in _run_callback
    ret = callback()
  File "/home/pi/moonraker-env/lib/python3.9/site-packages/tornado/simple_httpclient.py", line 287, in <lambda>
    gen.convert_yielded(self.run()), lambda f: f.result()
  File "/home/pi/moonraker-env/lib/python3.9/site-packages/tornado/simple_httpclient.py", line 340, in run
    stream = await self.tcp_client.connect(
  File "/home/pi/moonraker-env/lib/python3.9/site-packages/tornado/tcpclient.py", line 269, in connect
    addrinfo = await self.resolver.resolve(host, port, af)
  File "/home/pi/moonraker-env/lib/python3.9/site-packages/tornado/netutil.py", line 433, in resolve
    for fam, _, _, _, address in await asyncio.get_running_loop().getaddrinfo(
  File "/usr/lib/python3.9/asyncio/base_events.py", line 856, in getaddrinfo
    return await self.run_in_executor(
  File "/usr/lib/python3.9/concurrent/futures/thread.py", line 52, in run
    result = self.fn(*self.args, **self.kwargs)
  File "/usr/lib/python3.9/socket.py", line 953, in getaddrinfo
    for res in _socket.getaddrinfo(host, port, family, type, proto, flags):
socket.gaierror: [Errno -3] Temporary failure in name resolution
2024-11-23 01:39:24,955 [machine.py:_find_public_ip()] - Detected Local IP: 192.168.1.224
2024-11-23 01:50:48,275 [ioloop.py:_run_callback()] - Exception in callback functools.partial(<function _HTTPConnection.__init__.<locals>.<lambda> at 0xf15b7220>, <Task finished name='Task-2325280' coro=<_HTTPConnection.run() done, defined at /home/pi/moonraker-env/lib/python3.9/site-packages/tornado/simple_httpclient.py:290> exception=gaierror(-3, 'Temporary failure in name resolution')>)
Traceback (most recent call last):
  File "/home/pi/moonraker-env/lib/python3.9/site-packages/tornado/ioloop.py", line 750, in _run_callback
    ret = callback()
  File "/home/pi/moonraker-env/lib/python3.9/site-packages/tornado/simple_httpclient.py", line 287, in <lambda>
    gen.convert_yielded(self.run()), lambda f: f.result()
  File "/home/pi/moonraker-env/lib/python3.9/site-packages/tornado/simple_httpclient.py", line 340, in run
    stream = await self.tcp_client.connect(
  File "/home/pi/moonraker-env/lib/python3.9/site-packages/tornado/tcpclient.py", line 269, in connect
    addrinfo = await self.resolver.resolve(host, port, af)
  File "/home/pi/moonraker-env/lib/python3.9/site-packages/tornado/netutil.py", line 433, in resolve
    for fam, _, _, _, address in await asyncio.get_running_loop().getaddrinfo(
  File "/usr/lib/python3.9/asyncio/base_events.py", line 856, in getaddrinfo
    return await self.run_in_executor(
  File "/usr/lib/python3.9/concurrent/futures/thread.py", line 52, in run
    result = self.fn(*self.args, **self.kwargs)
  File "/usr/lib/python3.9/socket.py", line 953, in getaddrinfo
    for res in _socket.getaddrinfo(host, port, family, type, proto, flags):
socket.gaierror: [Errno -3] Temporary failure in name resolution
2024-11-23 01:50:51,555 [announcements.py:_fetch_moonlight()] - Failed to update subscription 'moonraker': Timeout while connecting
2024-11-23 01:50:54,415 [ioloop.py:_run_callback()] - Exception in callback functools.partial(<function _HTTPConnection.__init__.<locals>.<lambda> at 0xf1f69f58>, <Task finished name='Task-2325789' coro=<_HTTPConnection.run() done, defined at /home/pi/moonraker-env/lib/python3.9/site-packages/tornado/simple_httpclient.py:290> exception=gaierror(-3, 'Temporary failure in name resolution')>)
Traceback (most recent call last):
  File "/home/pi/moonraker-env/lib/python3.9/site-packages/tornado/ioloop.py", line 750, in _run_callback
    ret = callback()
  File "/home/pi/moonraker-env/lib/python3.9/site-packages/tornado/simple_httpclient.py", line 287, in <lambda>
    gen.convert_yielded(self.run()), lambda f: f.result()
  File "/home/pi/moonraker-env/lib/python3.9/site-packages/tornado/simple_httpclient.py", line 340, in run
    stream = await self.tcp_client.connect(
  File "/home/pi/moonraker-env/lib/python3.9/site-packages/tornado/tcpclient.py", line 269, in connect
    addrinfo = await self.resolver.resolve(host, port, af)
  File "/home/pi/moonraker-env/lib/python3.9/site-packages/tornado/netutil.py", line 433, in resolve
    for fam, _, _, _, address in await asyncio.get_running_loop().getaddrinfo(
  File "/usr/lib/python3.9/asyncio/base_events.py", line 856, in getaddrinfo
    return await self.run_in_executor(
  File "/usr/lib/python3.9/concurrent/futures/thread.py", line 52, in run
    result = self.fn(*self.args, **self.kwargs)
  File "/usr/lib/python3.9/socket.py", line 953, in getaddrinfo
    for res in _socket.getaddrinfo(host, port, family, type, proto, flags):
socket.gaierror: [Errno -3] Temporary failure in name resolution
2024-11-23 01:50:57,487 [ioloop.py:_run_callback()] - Exception in callback functools.partial(<function _HTTPConnection.__init__.<locals>.<lambda> at 0xf1f47fa0>, <Task finished name='Task-2326298' coro=<_HTTPConnection.run() done, defined at /home/pi/moonraker-env/lib/python3.9/site-packages/tornado/simple_httpclient.py:290> exception=gaierror(-3, 'Temporary failure in name resolution')>)
Traceback (most recent call last):
  File "/home/pi/moonraker-env/lib/python3.9/site-packages/tornado/ioloop.py", line 750, in _run_callback
    ret = callback()
  File "/home/pi/moonraker-env/lib/python3.9/site-packages/tornado/simple_httpclient.py", line 287, in <lambda>
    gen.convert_yielded(self.run()), lambda f: f.result()
  File "/home/pi/moonraker-env/lib/python3.9/site-packages/tornado/simple_httpclient.py", line 340, in run
    stream = await self.tcp_client.connect(
  File "/home/pi/moonraker-env/lib/python3.9/site-packages/tornado/tcpclient.py", line 269, in connect
    addrinfo = await self.resolver.resolve(host, port, af)
  File "/home/pi/moonraker-env/lib/python3.9/site-packages/tornado/netutil.py", line 433, in resolve
    for fam, _, _, _, address in await asyncio.get_running_loop().getaddrinfo(
  File "/usr/lib/python3.9/asyncio/base_events.py", line 856, in getaddrinfo
    return await self.run_in_executor(
  File "/usr/lib/python3.9/concurrent/futures/thread.py", line 52, in run
    result = self.fn(*self.args, **self.kwargs)
  File "/usr/lib/python3.9/socket.py", line 953, in getaddrinfo
    for res in _socket.getaddrinfo(host, port, family, type, proto, flags):
socket.gaierror: [Errno -3] Temporary failure in name resolution
2024-11-23 01:51:03,633 [ioloop.py:_run_callback()] - Exception in callback functools.partial(<function _HTTPConnection.__init__.<locals>.<lambda> at 0xf1f47808>, <Task finished name='Task-2326782' coro=<_HTTPConnection.run() done, defined at /home/pi/moonraker-env/lib/python3.9/site-packages/tornado/simple_httpclient.py:290> exception=gaierror(-3, 'Temporary failure in name resolution')>)
Traceback (most recent call last):
  File "/home/pi/moonraker-env/lib/python3.9/site-packages/tornado/ioloop.py", line 750, in _run_callback
    ret = callback()
  File "/home/pi/moonraker-env/lib/python3.9/site-packages/tornado/simple_httpclient.py", line 287, in <lambda>
    gen.convert_yielded(self.run()), lambda f: f.result()
  File "/home/pi/moonraker-env/lib/python3.9/site-packages/tornado/simple_httpclient.py", line 340, in run
    stream = await self.tcp_client.connect(
  File "/home/pi/moonraker-env/lib/python3.9/site-packages/tornado/tcpclient.py", line 269, in connect
    addrinfo = await self.resolver.resolve(host, port, af)
  File "/home/pi/moonraker-env/lib/python3.9/site-packages/tornado/netutil.py", line 433, in resolve
    for fam, _, _, _, address in await asyncio.get_running_loop().getaddrinfo(
  File "/usr/lib/python3.9/asyncio/base_events.py", line 856, in getaddrinfo
    return await self.run_in_executor(
  File "/usr/lib/python3.9/concurrent/futures/thread.py", line 52, in run
    result = self.fn(*self.args, **self.kwargs)
  File "/usr/lib/python3.9/socket.py", line 953, in getaddrinfo
    for res in _socket.getaddrinfo(host, port, family, type, proto, flags):
socket.gaierror: [Errno -3] Temporary failure in name resolution
2024-11-23 01:51:09,800 [ioloop.py:_run_callback()] - Exception in callback functools.partial(<function _HTTPConnection.__init__.<locals>.<lambda> at 0xf1f7c190>, <Task finished name='Task-2327303' coro=<_HTTPConnection.run() done, defined at /home/pi/moonraker-env/lib/python3.9/site-packages/tornado/simple_httpclient.py:290> exception=gaierror(-3, 'Temporary failure in name resolution')>)
Traceback (most recent call last):
  File "/home/pi/moonraker-env/lib/python3.9/site-packages/tornado/ioloop.py", line 750, in _run_callback
    ret = callback()
  File "/home/pi/moonraker-env/lib/python3.9/site-packages/tornado/simple_httpclient.py", line 287, in <lambda>
    gen.convert_yielded(self.run()), lambda f: f.result()
  File "/home/pi/moonraker-env/lib/python3.9/site-packages/tornado/simple_httpclient.py", line 340, in run
    stream = await self.tcp_client.connect(
  File "/home/pi/moonraker-env/lib/python3.9/site-packages/tornado/tcpclient.py", line 269, in connect
    addrinfo = await self.resolver.resolve(host, port, af)
  File "/home/pi/moonraker-env/lib/python3.9/site-packages/tornado/netutil.py", line 433, in resolve
    for fam, _, _, _, address in await asyncio.get_running_loop().getaddrinfo(
  File "/usr/lib/python3.9/asyncio/base_events.py", line 856, in getaddrinfo
    return await self.run_in_executor(
  File "/usr/lib/python3.9/concurrent/futures/thread.py", line 52, in run
    result = self.fn(*self.args, **self.kwargs)
  File "/usr/lib/python3.9/socket.py", line 953, in getaddrinfo
    for res in _socket.getaddrinfo(host, port, family, type, proto, flags):
socket.gaierror: [Errno -3] Temporary failure in name resolution
2024-11-23 01:51:15,922 [ioloop.py:_run_callback()] - Exception in callback functools.partial(<function _HTTPConnection.__init__.<locals>.<lambda> at 0xf15bee38>, <Task finished name='Task-2327755' coro=<_HTTPConnection.run() done, defined at /home/pi/moonraker-env/lib/python3.9/site-packages/tornado/simple_httpclient.py:290> exception=gaierror(-3, 'Temporary failure in name resolution')>)
Traceback (most recent call last):
  File "/home/pi/moonraker-env/lib/python3.9/site-packages/tornado/ioloop.py", line 750, in _run_callback
    ret = callback()
  File "/home/pi/moonraker-env/lib/python3.9/site-packages/tornado/simple_httpclient.py", line 287, in <lambda>
    gen.convert_yielded(self.run()), lambda f: f.result()
  File "/home/pi/moonraker-env/lib/python3.9/site-packages/tornado/simple_httpclient.py", line 340, in run
    stream = await self.tcp_client.connect(
  File "/home/pi/moonraker-env/lib/python3.9/site-packages/tornado/tcpclient.py", line 269, in connect
    addrinfo = await self.resolver.resolve(host, port, af)
  File "/home/pi/moonraker-env/lib/python3.9/site-packages/tornado/netutil.py", line 433, in resolve
    for fam, _, _, _, address in await asyncio.get_running_loop().getaddrinfo(
  File "/usr/lib/python3.9/asyncio/base_events.py", line 856, in getaddrinfo
    return await self.run_in_executor(
  File "/usr/lib/python3.9/concurrent/futures/thread.py", line 52, in run
    result = self.fn(*self.args, **self.kwargs)
  File "/usr/lib/python3.9/socket.py", line 953, in getaddrinfo
    for res in _socket.getaddrinfo(host, port, family, type, proto, flags):
socket.gaierror: [Errno -3] Temporary failure in name resolution
2024-11-23 01:51:18,569 [announcements.py:_fetch_moonlight()] - Failed to update subscription 'klipper': Timeout while connecting
2024-11-23 01:51:18,991 [ioloop.py:_run_callback()] - Exception in callback functools.partial(<function _HTTPConnection.__init__.<locals>.<lambda> at 0xf1f69460>, <Task finished name='Task-2328269' coro=<_HTTPConnection.run() done, defined at /home/pi/moonraker-env/lib/python3.9/site-packages/tornado/simple_httpclient.py:290> exception=gaierror(-3, 'Temporary failure in name resolution')>)
Traceback (most recent call last):
  File "/home/pi/moonraker-env/lib/python3.9/site-packages/tornado/ioloop.py", line 750, in _run_callback
    ret = callback()
  File "/home/pi/moonraker-env/lib/python3.9/site-packages/tornado/simple_httpclient.py", line 287, in <lambda>
    gen.convert_yielded(self.run()), lambda f: f.result()
  File "/home/pi/moonraker-env/lib/python3.9/site-packages/tornado/simple_httpclient.py", line 340, in run
    stream = await self.tcp_client.connect(
  File "/home/pi/moonraker-env/lib/python3.9/site-packages/tornado/tcpclient.py", line 269, in connect
    addrinfo = await self.resolver.resolve(host, port, af)
  File "/home/pi/moonraker-env/lib/python3.9/site-packages/tornado/netutil.py", line 433, in resolve
    for fam, _, _, _, address in await asyncio.get_running_loop().getaddrinfo(
  File "/usr/lib/python3.9/asyncio/base_events.py", line 856, in getaddrinfo
    return await self.run_in_executor(
  File "/usr/lib/python3.9/concurrent/futures/thread.py", line 52, in run
    result = self.fn(*self.args, **self.kwargs)
  File "/usr/lib/python3.9/socket.py", line 953, in getaddrinfo
    for res in _socket.getaddrinfo(host, port, family, type, proto, flags):
socket.gaierror: [Errno -3] Temporary failure in name resolution
2024-11-23 01:51:25,136 [ioloop.py:_run_callback()] - Exception in callback functools.partial(<function _HTTPConnection.__init__.<locals>.<lambda> at 0xf1f47658>, <Task finished name='Task-2328780' coro=<_HTTPConnection.run() done, defined at /home/pi/moonraker-env/lib/python3.9/site-packages/tornado/simple_httpclient.py:290> exception=gaierror(-3, 'Temporary failure in name resolution')>)
Traceback (most recent call last):
  File "/home/pi/moonraker-env/lib/python3.9/site-packages/tornado/ioloop.py", line 750, in _run_callback
    ret = callback()
  File "/home/pi/moonraker-env/lib/python3.9/site-packages/tornado/simple_httpclient.py", line 287, in <lambda>
    gen.convert_yielded(self.run()), lambda f: f.result()
  File "/home/pi/moonraker-env/lib/python3.9/site-packages/tornado/simple_httpclient.py", line 340, in run
    stream = await self.tcp_client.connect(
  File "/home/pi/moonraker-env/lib/python3.9/site-packages/tornado/tcpclient.py", line 269, in connect
    addrinfo = await self.resolver.resolve(host, port, af)
  File "/home/pi/moonraker-env/lib/python3.9/site-packages/tornado/netutil.py", line 433, in resolve
    for fam, _, _, _, address in await asyncio.get_running_loop().getaddrinfo(
  File "/usr/lib/python3.9/asyncio/base_events.py", line 856, in getaddrinfo
    return await self.run_in_executor(
  File "/usr/lib/python3.9/concurrent/futures/thread.py", line 52, in run
    result = self.fn(*self.args, **self.kwargs)
  File "/usr/lib/python3.9/socket.py", line 953, in getaddrinfo
    for res in _socket.getaddrinfo(host, port, family, type, proto, flags):
socket.gaierror: [Errno -3] Temporary failure in name resolution
2024-11-23 01:51:31,280 [ioloop.py:_run_callback()] - Exception in callback functools.partial(<function _HTTPConnection.__init__.<locals>.<lambda> at 0xf1f47e38>, <Task finished name='Task-2329270' coro=<_HTTPConnection.run() done, defined at /home/pi/moonraker-env/lib/python3.9/site-packages/tornado/simple_httpclient.py:290> exception=gaierror(-3, 'Temporary failure in name resolution')>)
Traceback (most recent call last):
  File "/home/pi/moonraker-env/lib/python3.9/site-packages/tornado/ioloop.py", line 750, in _run_callback
    ret = callback()
  File "/home/pi/moonraker-env/lib/python3.9/site-packages/tornado/simple_httpclient.py", line 287, in <lambda>
    gen.convert_yielded(self.run()), lambda f: f.result()
  File "/home/pi/moonraker-env/lib/python3.9/site-packages/tornado/simple_httpclient.py", line 340, in run
    stream = await self.tcp_client.connect(
  File "/home/pi/moonraker-env/lib/python3.9/site-packages/tornado/tcpclient.py", line 269, in connect
    addrinfo = await self.resolver.resolve(host, port, af)
  File "/home/pi/moonraker-env/lib/python3.9/site-packages/tornado/netutil.py", line 433, in resolve
    for fam, _, _, _, address in await asyncio.get_running_loop().getaddrinfo(
  File "/usr/lib/python3.9/asyncio/base_events.py", line 856, in getaddrinfo
    return await self.run_in_executor(
  File "/usr/lib/python3.9/concurrent/futures/thread.py", line 52, in run
    result = self.fn(*self.args, **self.kwargs)
  File "/usr/lib/python3.9/socket.py", line 953, in getaddrinfo
    for res in _socket.getaddrinfo(host, port, family, type, proto, flags):
socket.gaierror: [Errno -3] Temporary failure in name resolution
2024-11-23 01:51:37,423 [ioloop.py:_run_callback()] - Exception in callback functools.partial(<function _HTTPConnection.__init__.<locals>.<lambda> at 0xf1f7ce80>, <Task finished name='Task-2329783' coro=<_HTTPConnection.run() done, defined at /home/pi/moonraker-env/lib/python3.9/site-packages/tornado/simple_httpclient.py:290> exception=gaierror(-3, 'Temporary failure in name resolution')>)
Traceback (most recent call last):
  File "/home/pi/moonraker-env/lib/python3.9/site-packages/tornado/ioloop.py", line 750, in _run_callback
    ret = callback()
  File "/home/pi/moonraker-env/lib/python3.9/site-packages/tornado/simple_httpclient.py", line 287, in <lambda>
    gen.convert_yielded(self.run()), lambda f: f.result()
  File "/home/pi/moonraker-env/lib/python3.9/site-packages/tornado/simple_httpclient.py", line 340, in run
    stream = await self.tcp_client.connect(
  File "/home/pi/moonraker-env/lib/python3.9/site-packages/tornado/tcpclient.py", line 269, in connect
    addrinfo = await self.resolver.resolve(host, port, af)
  File "/home/pi/moonraker-env/lib/python3.9/site-packages/tornado/netutil.py", line 433, in resolve
    for fam, _, _, _, address in await asyncio.get_running_loop().getaddrinfo(
  File "/usr/lib/python3.9/asyncio/base_events.py", line 856, in getaddrinfo
    return await self.run_in_executor(
  File "/usr/lib/python3.9/concurrent/futures/thread.py", line 52, in run
    result = self.fn(*self.args, **self.kwargs)
  File "/usr/lib/python3.9/socket.py", line 953, in getaddrinfo
    for res in _socket.getaddrinfo(host, port, family, type, proto, flags):
socket.gaierror: [Errno -3] Temporary failure in name resolution
2024-11-23 01:51:40,497 [ioloop.py:_run_callback()] - Exception in callback functools.partial(<function _HTTPConnection.__init__.<locals>.<lambda> at 0xf15bef58>, <Task finished name='Task-2330219' coro=<_HTTPConnection.run() done, defined at /home/pi/moonraker-env/lib/python3.9/site-packages/tornado/simple_httpclient.py:290> exception=gaierror(-3, 'Temporary failure in name resolution')>)
Traceback (most recent call last):
  File "/home/pi/moonraker-env/lib/python3.9/site-packages/tornado/ioloop.py", line 750, in _run_callback
    ret = callback()
  File "/home/pi/moonraker-env/lib/python3.9/site-packages/tornado/simple_httpclient.py", line 287, in <lambda>
    gen.convert_yielded(self.run()), lambda f: f.result()
  File "/home/pi/moonraker-env/lib/python3.9/site-packages/tornado/simple_httpclient.py", line 340, in run
    stream = await self.tcp_client.connect(
  File "/home/pi/moonraker-env/lib/python3.9/site-packages/tornado/tcpclient.py", line 269, in connect
    addrinfo = await self.resolver.resolve(host, port, af)
  File "/home/pi/moonraker-env/lib/python3.9/site-packages/tornado/netutil.py", line 433, in resolve
    for fam, _, _, _, address in await asyncio.get_running_loop().getaddrinfo(
  File "/usr/lib/python3.9/asyncio/base_events.py", line 856, in getaddrinfo
    return await self.run_in_executor(
  File "/usr/lib/python3.9/concurrent/futures/thread.py", line 52, in run
    result = self.fn(*self.args, **self.kwargs)
  File "/usr/lib/python3.9/socket.py", line 953, in getaddrinfo
    for res in _socket.getaddrinfo(host, port, family, type, proto, flags):
socket.gaierror: [Errno -3] Temporary failure in name resolution
2024-11-23 01:51:45,581 [announcements.py:_fetch_moonlight()] - Failed to update subscription 'moonraker-telegram-bot': Timeout while connecting
2024-11-23 01:51:46,666 [ioloop.py:_run_callback()] - Exception in callback functools.partial(<function _HTTPConnection.__init__.<locals>.<lambda> at 0xf1f7c970>, <Task finished name='Task-2330751' coro=<_HTTPConnection.run() done, defined at /home/pi/moonraker-env/lib/python3.9/site-packages/tornado/simple_httpclient.py:290> exception=gaierror(-3, 'Temporary failure in name resolution')>)
Traceback (most recent call last):
  File "/home/pi/moonraker-env/lib/python3.9/site-packages/tornado/ioloop.py", line 750, in _run_callback
    ret = callback()
  File "/home/pi/moonraker-env/lib/python3.9/site-packages/tornado/simple_httpclient.py", line 287, in <lambda>
    gen.convert_yielded(self.run()), lambda f: f.result()
  File "/home/pi/moonraker-env/lib/python3.9/site-packages/tornado/simple_httpclient.py", line 340, in run
    stream = await self.tcp_client.connect(
  File "/home/pi/moonraker-env/lib/python3.9/site-packages/tornado/tcpclient.py", line 269, in connect
    addrinfo = await self.resolver.resolve(host, port, af)
  File "/home/pi/moonraker-env/lib/python3.9/site-packages/tornado/netutil.py", line 433, in resolve
    for fam, _, _, _, address in await asyncio.get_running_loop().getaddrinfo(
  File "/usr/lib/python3.9/asyncio/base_events.py", line 856, in getaddrinfo
    return await self.run_in_executor(
  File "/usr/lib/python3.9/concurrent/futures/thread.py", line 52, in run
    result = self.fn(*self.args, **self.kwargs)
  File "/usr/lib/python3.9/socket.py", line 953, in getaddrinfo
    for res in _socket.getaddrinfo(host, port, family, type, proto, flags):
socket.gaierror: [Errno -3] Temporary failure in name resolution
2024-11-23 01:51:52,789 [ioloop.py:_run_callback()] - Exception in callback functools.partial(<function _HTTPConnection.__init__.<locals>.<lambda> at 0xf1f479b8>, <Task finished name='Task-2331259' coro=<_HTTPConnection.run() done, defined at /home/pi/moonraker-env/lib/python3.9/site-packages/tornado/simple_httpclient.py:290> exception=gaierror(-3, 'Temporary failure in name resolution')>)
Traceback (most recent call last):
  File "/home/pi/moonraker-env/lib/python3.9/site-packages/tornado/ioloop.py", line 750, in _run_callback
    ret = callback()
  File "/home/pi/moonraker-env/lib/python3.9/site-packages/tornado/simple_httpclient.py", line 287, in <lambda>
    gen.convert_yielded(self.run()), lambda f: f.result()
  File "/home/pi/moonraker-env/lib/python3.9/site-packages/tornado/simple_httpclient.py", line 340, in run
    stream = await self.tcp_client.connect(
  File "/home/pi/moonraker-env/lib/python3.9/site-packages/tornado/tcpclient.py", line 269, in connect
    addrinfo = await self.resolver.resolve(host, port, af)
  File "/home/pi/moonraker-env/lib/python3.9/site-packages/tornado/netutil.py", line 433, in resolve
    for fam, _, _, _, address in await asyncio.get_running_loop().getaddrinfo(
  File "/usr/lib/python3.9/asyncio/base_events.py", line 856, in getaddrinfo
    return await self.run_in_executor(
  File "/usr/lib/python3.9/concurrent/futures/thread.py", line 52, in run
    result = self.fn(*self.args, **self.kwargs)
  File "/usr/lib/python3.9/socket.py", line 953, in getaddrinfo
    for res in _socket.getaddrinfo(host, port, family, type, proto, flags):
socket.gaierror: [Errno -3] Temporary failure in name resolution
2024-11-23 01:51:58,928 [ioloop.py:_run_callback()] - Exception in callback functools.partial(<function _HTTPConnection.__init__.<locals>.<lambda> at 0xf1f7c0b8>, <Task finished name='Task-2331745' coro=<_HTTPConnection.run() done, defined at /home/pi/moonraker-env/lib/python3.9/site-packages/tornado/simple_httpclient.py:290> exception=gaierror(-3, 'Temporary failure in name resolution')>)
Traceback (most recent call last):
  File "/home/pi/moonraker-env/lib/python3.9/site-packages/tornado/ioloop.py", line 750, in _run_callback
    ret = callback()
  File "/home/pi/moonraker-env/lib/python3.9/site-packages/tornado/simple_httpclient.py", line 287, in <lambda>
    gen.convert_yielded(self.run()), lambda f: f.result()
  File "/home/pi/moonraker-env/lib/python3.9/site-packages/tornado/simple_httpclient.py", line 340, in run
    stream = await self.tcp_client.connect(
  File "/home/pi/moonraker-env/lib/python3.9/site-packages/tornado/tcpclient.py", line 269, in connect
    addrinfo = await self.resolver.resolve(host, port, af)
  File "/home/pi/moonraker-env/lib/python3.9/site-packages/tornado/netutil.py", line 433, in resolve
    for fam, _, _, _, address in await asyncio.get_running_loop().getaddrinfo(
  File "/usr/lib/python3.9/asyncio/base_events.py", line 856, in getaddrinfo
    return await self.run_in_executor(
  File "/usr/lib/python3.9/concurrent/futures/thread.py", line 52, in run
    result = self.fn(*self.args, **self.kwargs)
  File "/usr/lib/python3.9/socket.py", line 953, in getaddrinfo
    for res in _socket.getaddrinfo(host, port, family, type, proto, flags):
socket.gaierror: [Errno -3] Temporary failure in name resolution
2024-11-23 01:52:05,088 [ioloop.py:_run_callback()] - Exception in callback functools.partial(<function _HTTPConnection.__init__.<locals>.<lambda> at 0xf1f69f58>, <Task finished name='Task-2332259' coro=<_HTTPConnection.run() done, defined at /home/pi/moonraker-env/lib/python3.9/site-packages/tornado/simple_httpclient.py:290> exception=gaierror(-3, 'Temporary failure in name resolution')>)
Traceback (most recent call last):
  File "/home/pi/moonraker-env/lib/python3.9/site-packages/tornado/ioloop.py", line 750, in _run_callback
    ret = callback()
  File "/home/pi/moonraker-env/lib/python3.9/site-packages/tornado/simple_httpclient.py", line 287, in <lambda>
    gen.convert_yielded(self.run()), lambda f: f.result()
  File "/home/pi/moonraker-env/lib/python3.9/site-packages/tornado/simple_httpclient.py", line 340, in run
    stream = await self.tcp_client.connect(
  File "/home/pi/moonraker-env/lib/python3.9/site-packages/tornado/tcpclient.py", line 269, in connect
    addrinfo = await self.resolver.resolve(host, port, af)
  File "/home/pi/moonraker-env/lib/python3.9/site-packages/tornado/netutil.py", line 433, in resolve
    for fam, _, _, _, address in await asyncio.get_running_loop().getaddrinfo(
  File "/usr/lib/python3.9/asyncio/base_events.py", line 856, in getaddrinfo
    return await self.run_in_executor(
  File "/usr/lib/python3.9/concurrent/futures/thread.py", line 52, in run
    result = self.fn(*self.args, **self.kwargs)
  File "/usr/lib/python3.9/socket.py", line 953, in getaddrinfo
    for res in _socket.getaddrinfo(host, port, family, type, proto, flags):
socket.gaierror: [Errno -3] Temporary failure in name resolution
2024-11-23 01:56:16,050 [machine.py:_find_public_ip()] - Detected Local IP: 192.168.1.224
2024-11-23 02:19:47,686 [machine.py:_find_public_ip()] - Failed to detect local IP address
2024-11-23 02:19:47,691 [webcam.py:_set_default_host_ip()] - Default public webcam address set: http://127.0.0.1
2024-11-23 02:19:52,513 [websockets.py:write_to_socket()] - Websocket closed while writing: 4070386776
2024-11-23 02:19:57,498 [websockets.py:on_close()] - Websocket Closed: ID: 4070386776 Close Code: None, Close Reason: None, Pong Time Elapsed: 35.00
2024-11-23 02:19:57,692 [machine.py:_find_public_ip()] - Detected Local IP: 169.254.85.87
2024-11-23 02:19:57,694 [webcam.py:_set_default_host_ip()] - Default public webcam address set: http://169.254.85.87
2024-11-23 02:20:07,275 [websockets.py:on_close()] - Websocket Closed: ID: 4089013608 Close Code: None, Close Reason: None, Pong Time Elapsed: 45.00
2024-11-23 02:20:07,276 [websockets.py:write_to_socket()] - Websocket closed while writing: 4089013608
2024-11-23 02:20:07,812 [websockets.py:on_close()] - Websocket Closed: ID: 4059931768 Close Code: None, Close Reason: None, Pong Time Elapsed: 45.00
2024-11-23 02:20:07,813 [websockets.py:write_to_socket()] - Websocket closed while writing: 4059931768
2024-11-23 02:20:08,579 [websockets.py:on_close()] - Websocket Closed: ID: 4088785864 Close Code: None, Close Reason: None, Pong Time Elapsed: 45.00
2024-11-23 02:20:08,580 [websockets.py:write_to_socket()] - Websocket closed while writing: 4088785864
2024-11-23 02:20:09,056 [websockets.py:on_close()] - Websocket Closed: ID: 4049358056 Close Code: None, Close Reason: None, Pong Time Elapsed: 45.00
2024-11-23 02:20:09,056 [websockets.py:write_to_socket()] - Websocket closed while writing: 4049358056
2024-11-23 02:20:15,080 [websockets.py:write_to_socket()] - Websocket closed while writing: 4070128752
2024-11-23 02:20:18,194 [websockets.py:on_close()] - Websocket Closed: ID: 4088768640 Close Code: None, Close Reason: None, Pong Time Elapsed: 45.00
2024-11-23 02:20:18,196 [websockets.py:write_to_socket()] - Websocket closed while writing: 4088768640
2024-11-23 02:20:19,898 [websockets.py:on_close()] - Websocket Closed: ID: 4070128752 Close Code: None, Close Reason: None, Pong Time Elapsed: 45.00
2024-11-23 02:20:35,157 [ioloop.py:_run_callback()] - Exception in callback functools.partial(<function _HTTPConnection.__init__.<locals>.<lambda> at 0xf29f8190>, <Task finished name='Task-2487471' coro=<_HTTPConnection.run() done, defined at /home/pi/moonraker-env/lib/python3.9/site-packages/tornado/simple_httpclient.py:290> exception=gaierror(-3, 'Temporary failure in name resolution')>)
Traceback (most recent call last):
  File "/home/pi/moonraker-env/lib/python3.9/site-packages/tornado/ioloop.py", line 750, in _run_callback
    ret = callback()
  File "/home/pi/moonraker-env/lib/python3.9/site-packages/tornado/simple_httpclient.py", line 287, in <lambda>
    gen.convert_yielded(self.run()), lambda f: f.result()
  File "/home/pi/moonraker-env/lib/python3.9/site-packages/tornado/simple_httpclient.py", line 340, in run
    stream = await self.tcp_client.connect(
  File "/home/pi/moonraker-env/lib/python3.9/site-packages/tornado/tcpclient.py", line 269, in connect
    addrinfo = await self.resolver.resolve(host, port, af)
  File "/home/pi/moonraker-env/lib/python3.9/site-packages/tornado/netutil.py", line 433, in resolve
    for fam, _, _, _, address in await asyncio.get_running_loop().getaddrinfo(
  File "/usr/lib/python3.9/asyncio/base_events.py", line 856, in getaddrinfo
    return await self.run_in_executor(
  File "/usr/lib/python3.9/concurrent/futures/thread.py", line 52, in run
    result = self.fn(*self.args, **self.kwargs)
  File "/usr/lib/python3.9/socket.py", line 953, in getaddrinfo
    for res in _socket.getaddrinfo(host, port, family, type, proto, flags):
socket.gaierror: [Errno -3] Temporary failure in name resolution
2024-11-23 02:20:44,847 [ioloop.py:_run_callback()] - Exception in callback functools.partial(<function _HTTPConnection.__init__.<locals>.<lambda> at 0xf2953898>, <Task finished name='Task-2487624' coro=<_HTTPConnection.run() done, defined at /home/pi/moonraker-env/lib/python3.9/site-packages/tornado/simple_httpclient.py:290> exception=gaierror(-3, 'Temporary failure in name resolution')>)
Traceback (most recent call last):
  File "/home/pi/moonraker-env/lib/python3.9/site-packages/tornado/ioloop.py", line 750, in _run_callback
    ret = callback()
  File "/home/pi/moonraker-env/lib/python3.9/site-packages/tornado/simple_httpclient.py", line 287, in <lambda>
    gen.convert_yielded(self.run()), lambda f: f.result()
  File "/home/pi/moonraker-env/lib/python3.9/site-packages/tornado/simple_httpclient.py", line 340, in run
    stream = await self.tcp_client.connect(
  File "/home/pi/moonraker-env/lib/python3.9/site-packages/tornado/tcpclient.py", line 269, in connect
    addrinfo = await self.resolver.resolve(host, port, af)
  File "/home/pi/moonraker-env/lib/python3.9/site-packages/tornado/netutil.py", line 433, in resolve
    for fam, _, _, _, address in await asyncio.get_running_loop().getaddrinfo(
  File "/usr/lib/python3.9/asyncio/base_events.py", line 856, in getaddrinfo
    return await self.run_in_executor(
  File "/usr/lib/python3.9/concurrent/futures/thread.py", line 52, in run
    result = self.fn(*self.args, **self.kwargs)
  File "/usr/lib/python3.9/socket.py", line 953, in getaddrinfo
    for res in _socket.getaddrinfo(host, port, family, type, proto, flags):
socket.gaierror: [Errno -3] Temporary failure in name resolution
2024-11-23 02:20:47,925 [announcements.py:_fetch_moonlight()] - Failed to update subscription 'moonraker': [Errno -3] Temporary failure in name resolution
2024-11-23 02:20:54,063 [ioloop.py:_run_callback()] - Exception in callback functools.partial(<function _HTTPConnection.__init__.<locals>.<lambda> at 0xf3b97808>, <Task finished name='Task-2487770' coro=<_HTTPConnection.run() done, defined at /home/pi/moonraker-env/lib/python3.9/site-packages/tornado/simple_httpclient.py:290> exception=gaierror(-3, 'Temporary failure in name resolution')>)
Traceback (most recent call last):
  File "/home/pi/moonraker-env/lib/python3.9/site-packages/tornado/ioloop.py", line 750, in _run_callback
    ret = callback()
  File "/home/pi/moonraker-env/lib/python3.9/site-packages/tornado/simple_httpclient.py", line 287, in <lambda>
    gen.convert_yielded(self.run()), lambda f: f.result()
  File "/home/pi/moonraker-env/lib/python3.9/site-packages/tornado/simple_httpclient.py", line 340, in run
    stream = await self.tcp_client.connect(
  File "/home/pi/moonraker-env/lib/python3.9/site-packages/tornado/tcpclient.py", line 269, in connect
    addrinfo = await self.resolver.resolve(host, port, af)
  File "/home/pi/moonraker-env/lib/python3.9/site-packages/tornado/netutil.py", line 433, in resolve
    for fam, _, _, _, address in await asyncio.get_running_loop().getaddrinfo(
  File "/usr/lib/python3.9/asyncio/base_events.py", line 856, in getaddrinfo
    return await self.run_in_executor(
  File "/usr/lib/python3.9/concurrent/futures/thread.py", line 52, in run
    result = self.fn(*self.args, **self.kwargs)
  File "/usr/lib/python3.9/socket.py", line 953, in getaddrinfo
    for res in _socket.getaddrinfo(host, port, family, type, proto, flags):
socket.gaierror: [Errno -3] Temporary failure in name resolution
2024-11-23 02:21:03,792 [ioloop.py:_run_callback()] - Exception in callback functools.partial(<function _HTTPConnection.__init__.<locals>.<lambda> at 0xf3b972f8>, <Task finished name='Task-2487921' coro=<_HTTPConnection.run() done, defined at /home/pi/moonraker-env/lib/python3.9/site-packages/tornado/simple_httpclient.py:290> exception=gaierror(-3, 'Temporary failure in name resolution')>)
Traceback (most recent call last):
  File "/home/pi/moonraker-env/lib/python3.9/site-packages/tornado/ioloop.py", line 750, in _run_callback
    ret = callback()
  File "/home/pi/moonraker-env/lib/python3.9/site-packages/tornado/simple_httpclient.py", line 287, in <lambda>
    gen.convert_yielded(self.run()), lambda f: f.result()
  File "/home/pi/moonraker-env/lib/python3.9/site-packages/tornado/simple_httpclient.py", line 340, in run
    stream = await self.tcp_client.connect(
  File "/home/pi/moonraker-env/lib/python3.9/site-packages/tornado/tcpclient.py", line 269, in connect
    addrinfo = await self.resolver.resolve(host, port, af)
  File "/home/pi/moonraker-env/lib/python3.9/site-packages/tornado/netutil.py", line 433, in resolve
    for fam, _, _, _, address in await asyncio.get_running_loop().getaddrinfo(
  File "/usr/lib/python3.9/asyncio/base_events.py", line 856, in getaddrinfo
    return await self.run_in_executor(
  File "/usr/lib/python3.9/concurrent/futures/thread.py", line 52, in run
    result = self.fn(*self.args, **self.kwargs)
  File "/usr/lib/python3.9/socket.py", line 953, in getaddrinfo
    for res in _socket.getaddrinfo(host, port, family, type, proto, flags):
socket.gaierror: [Errno -3] Temporary failure in name resolution
2024-11-23 02:21:12,366 [announcements.py:_fetch_moonlight()] - Failed to update subscription 'klipper': Timeout while connecting
2024-11-23 02:21:13,008 [ioloop.py:_run_callback()] - Exception in callback functools.partial(<function _HTTPConnection.__init__.<locals>.<lambda> at 0xf3b970b8>, <Task finished name='Task-2488082' coro=<_HTTPConnection.run() done, defined at /home/pi/moonraker-env/lib/python3.9/site-packages/tornado/simple_httpclient.py:290> exception=gaierror(-3, 'Temporary failure in name resolution')>)
Traceback (most recent call last):
  File "/home/pi/moonraker-env/lib/python3.9/site-packages/tornado/ioloop.py", line 750, in _run_callback
    ret = callback()
  File "/home/pi/moonraker-env/lib/python3.9/site-packages/tornado/simple_httpclient.py", line 287, in <lambda>
    gen.convert_yielded(self.run()), lambda f: f.result()
  File "/home/pi/moonraker-env/lib/python3.9/site-packages/tornado/simple_httpclient.py", line 340, in run
    stream = await self.tcp_client.connect(
  File "/home/pi/moonraker-env/lib/python3.9/site-packages/tornado/tcpclient.py", line 269, in connect
    addrinfo = await self.resolver.resolve(host, port, af)
  File "/home/pi/moonraker-env/lib/python3.9/site-packages/tornado/netutil.py", line 433, in resolve
    for fam, _, _, _, address in await asyncio.get_running_loop().getaddrinfo(
  File "/usr/lib/python3.9/asyncio/base_events.py", line 856, in getaddrinfo
    return await self.run_in_executor(
  File "/usr/lib/python3.9/concurrent/futures/thread.py", line 52, in run
    result = self.fn(*self.args, **self.kwargs)
  File "/usr/lib/python3.9/socket.py", line 953, in getaddrinfo
    for res in _socket.getaddrinfo(host, port, family, type, proto, flags):
socket.gaierror: [Errno -3] Temporary failure in name resolution
2024-11-23 02:21:22,224 [ioloop.py:_run_callback()] - Exception in callback functools.partial(<function _HTTPConnection.__init__.<locals>.<lambda> at 0xf3b42658>, <Task finished name='Task-2488234' coro=<_HTTPConnection.run() done, defined at /home/pi/moonraker-env/lib/python3.9/site-packages/tornado/simple_httpclient.py:290> exception=gaierror(-3, 'Temporary failure in name resolution')>)
Traceback (most recent call last):
  File "/home/pi/moonraker-env/lib/python3.9/site-packages/tornado/ioloop.py", line 750, in _run_callback
    ret = callback()
  File "/home/pi/moonraker-env/lib/python3.9/site-packages/tornado/simple_httpclient.py", line 287, in <lambda>
    gen.convert_yielded(self.run()), lambda f: f.result()
  File "/home/pi/moonraker-env/lib/python3.9/site-packages/tornado/simple_httpclient.py", line 340, in run
    stream = await self.tcp_client.connect(
  File "/home/pi/moonraker-env/lib/python3.9/site-packages/tornado/tcpclient.py", line 269, in connect
    addrinfo = await self.resolver.resolve(host, port, af)
  File "/home/pi/moonraker-env/lib/python3.9/site-packages/tornado/netutil.py", line 433, in resolve
    for fam, _, _, _, address in await asyncio.get_running_loop().getaddrinfo(
  File "/usr/lib/python3.9/asyncio/base_events.py", line 856, in getaddrinfo
    return await self.run_in_executor(
  File "/usr/lib/python3.9/concurrent/futures/thread.py", line 52, in run
    result = self.fn(*self.args, **self.kwargs)
  File "/usr/lib/python3.9/socket.py", line 953, in getaddrinfo
    for res in _socket.getaddrinfo(host, port, family, type, proto, flags):
socket.gaierror: [Errno -3] Temporary failure in name resolution
2024-11-23 02:21:31,440 [ioloop.py:_run_callback()] - Exception in callback functools.partial(<function _HTTPConnection.__init__.<locals>.<lambda> at 0xf3b97808>, <Task finished name='Task-2488383' coro=<_HTTPConnection.run() done, defined at /home/pi/moonraker-env/lib/python3.9/site-packages/tornado/simple_httpclient.py:290> exception=gaierror(-3, 'Temporary failure in name resolution')>)
Traceback (most recent call last):
  File "/home/pi/moonraker-env/lib/python3.9/site-packages/tornado/ioloop.py", line 750, in _run_callback
    ret = callback()
  File "/home/pi/moonraker-env/lib/python3.9/site-packages/tornado/simple_httpclient.py", line 287, in <lambda>
    gen.convert_yielded(self.run()), lambda f: f.result()
  File "/home/pi/moonraker-env/lib/python3.9/site-packages/tornado/simple_httpclient.py", line 340, in run
    stream = await self.tcp_client.connect(
  File "/home/pi/moonraker-env/lib/python3.9/site-packages/tornado/tcpclient.py", line 269, in connect
    addrinfo = await self.resolver.resolve(host, port, af)
  File "/home/pi/moonraker-env/lib/python3.9/site-packages/tornado/netutil.py", line 433, in resolve
    for fam, _, _, _, address in await asyncio.get_running_loop().getaddrinfo(
  File "/usr/lib/python3.9/asyncio/base_events.py", line 856, in getaddrinfo
    return await self.run_in_executor(
  File "/usr/lib/python3.9/concurrent/futures/thread.py", line 52, in run
    result = self.fn(*self.args, **self.kwargs)
  File "/usr/lib/python3.9/socket.py", line 953, in getaddrinfo
    for res in _socket.getaddrinfo(host, port, family, type, proto, flags):
socket.gaierror: [Errno -3] Temporary failure in name resolution
2024-11-23 02:21:34,512 [announcements.py:_fetch_moonlight()] - Failed to update subscription 'moonraker-telegram-bot': [Errno -3] Temporary failure in name resolution
2024-11-23 02:50:29,935 [ioloop.py:_run_callback()] - Exception in callback functools.partial(<function _HTTPConnection.__init__.<locals>.<lambda> at 0xf29d3bb0>, <Task finished name='Task-2517176' coro=<_HTTPConnection.run() done, defined at /home/pi/moonraker-env/lib/python3.9/site-packages/tornado/simple_httpclient.py:290> exception=gaierror(-3, 'Temporary failure in name resolution')>)
Traceback (most recent call last):
  File "/home/pi/moonraker-env/lib/python3.9/site-packages/tornado/ioloop.py", line 750, in _run_callback
    ret = callback()
  File "/home/pi/moonraker-env/lib/python3.9/site-packages/tornado/simple_httpclient.py", line 287, in <lambda>
    gen.convert_yielded(self.run()), lambda f: f.result()
  File "/home/pi/moonraker-env/lib/python3.9/site-packages/tornado/simple_httpclient.py", line 340, in run
    stream = await self.tcp_client.connect(
  File "/home/pi/moonraker-env/lib/python3.9/site-packages/tornado/tcpclient.py", line 269, in connect
    addrinfo = await self.resolver.resolve(host, port, af)
  File "/home/pi/moonraker-env/lib/python3.9/site-packages/tornado/netutil.py", line 433, in resolve
    for fam, _, _, _, address in await asyncio.get_running_loop().getaddrinfo(
  File "/usr/lib/python3.9/asyncio/base_events.py", line 856, in getaddrinfo
    return await self.run_in_executor(
  File "/usr/lib/python3.9/concurrent/futures/thread.py", line 52, in run
    result = self.fn(*self.args, **self.kwargs)
  File "/usr/lib/python3.9/socket.py", line 953, in getaddrinfo
    for res in _socket.getaddrinfo(host, port, family, type, proto, flags):
socket.gaierror: [Errno -3] Temporary failure in name resolution
2024-11-23 02:50:36,175 [ioloop.py:_run_callback()] - Exception in callback functools.partial(<function _HTTPConnection.__init__.<locals>.<lambda> at 0xf3b970b8>, <Task finished name='Task-2517273' coro=<_HTTPConnection.run() done, defined at /home/pi/moonraker-env/lib/python3.9/site-packages/tornado/simple_httpclient.py:290> exception=gaierror(-3, 'Temporary failure in name resolution')>)
Traceback (most recent call last):
  File "/home/pi/moonraker-env/lib/python3.9/site-packages/tornado/ioloop.py", line 750, in _run_callback
    ret = callback()
  File "/home/pi/moonraker-env/lib/python3.9/site-packages/tornado/simple_httpclient.py", line 287, in <lambda>
    gen.convert_yielded(self.run()), lambda f: f.result()
  File "/home/pi/moonraker-env/lib/python3.9/site-packages/tornado/simple_httpclient.py", line 340, in run
    stream = await self.tcp_client.connect(
  File "/home/pi/moonraker-env/lib/python3.9/site-packages/tornado/tcpclient.py", line 269, in connect
    addrinfo = await self.resolver.resolve(host, port, af)
  File "/home/pi/moonraker-env/lib/python3.9/site-packages/tornado/netutil.py", line 433, in resolve
    for fam, _, _, _, address in await asyncio.get_running_loop().getaddrinfo(
  File "/usr/lib/python3.9/asyncio/base_events.py", line 856, in getaddrinfo
    return await self.run_in_executor(
  File "/usr/lib/python3.9/concurrent/futures/thread.py", line 52, in run
    result = self.fn(*self.args, **self.kwargs)
  File "/usr/lib/python3.9/socket.py", line 953, in getaddrinfo
    for res in _socket.getaddrinfo(host, port, family, type, proto, flags):
socket.gaierror: [Errno -3] Temporary failure in name resolution
2024-11-23 02:50:45,872 [ioloop.py:_run_callback()] - Exception in callback functools.partial(<function _HTTPConnection.__init__.<locals>.<lambda> at 0xf29f8190>, <Task finished name='Task-2517440' coro=<_HTTPConnection.run() done, defined at /home/pi/moonraker-env/lib/python3.9/site-packages/tornado/simple_httpclient.py:290> exception=gaierror(-3, 'Temporary failure in name resolution')>)
Traceback (most recent call last):
  File "/home/pi/moonraker-env/lib/python3.9/site-packages/tornado/ioloop.py", line 750, in _run_callback
    ret = callback()
  File "/home/pi/moonraker-env/lib/python3.9/site-packages/tornado/simple_httpclient.py", line 287, in <lambda>
    gen.convert_yielded(self.run()), lambda f: f.result()
  File "/home/pi/moonraker-env/lib/python3.9/site-packages/tornado/simple_httpclient.py", line 340, in run
    stream = await self.tcp_client.connect(
  File "/home/pi/moonraker-env/lib/python3.9/site-packages/tornado/tcpclient.py", line 269, in connect
    addrinfo = await self.resolver.resolve(host, port, af)
  File "/home/pi/moonraker-env/lib/python3.9/site-packages/tornado/netutil.py", line 433, in resolve
    for fam, _, _, _, address in await asyncio.get_running_loop().getaddrinfo(
  File "/usr/lib/python3.9/asyncio/base_events.py", line 856, in getaddrinfo
    return await self.run_in_executor(
  File "/usr/lib/python3.9/concurrent/futures/thread.py", line 52, in run
    result = self.fn(*self.args, **self.kwargs)
  File "/usr/lib/python3.9/socket.py", line 953, in getaddrinfo
    for res in _socket.getaddrinfo(host, port, family, type, proto, flags):
socket.gaierror: [Errno -3] Temporary failure in name resolution
2024-11-23 02:50:48,943 [announcements.py:_fetch_moonlight()] - Failed to update subscription 'moonraker': [Errno -3] Temporary failure in name resolution
2024-11-23 02:50:55,087 [ioloop.py:_run_callback()] - Exception in callback functools.partial(<function _HTTPConnection.__init__.<locals>.<lambda> at 0xf3b972f8>, <Task finished name='Task-2517592' coro=<_HTTPConnection.run() done, defined at /home/pi/moonraker-env/lib/python3.9/site-packages/tornado/simple_httpclient.py:290> exception=gaierror(-3, 'Temporary failure in name resolution')>)
Traceback (most recent call last):
  File "/home/pi/moonraker-env/lib/python3.9/site-packages/tornado/ioloop.py", line 750, in _run_callback
    ret = callback()
  File "/home/pi/moonraker-env/lib/python3.9/site-packages/tornado/simple_httpclient.py", line 287, in <lambda>
    gen.convert_yielded(self.run()), lambda f: f.result()
  File "/home/pi/moonraker-env/lib/python3.9/site-packages/tornado/simple_httpclient.py", line 340, in run
    stream = await self.tcp_client.connect(
  File "/home/pi/moonraker-env/lib/python3.9/site-packages/tornado/tcpclient.py", line 269, in connect
    addrinfo = await self.resolver.resolve(host, port, af)
  File "/home/pi/moonraker-env/lib/python3.9/site-packages/tornado/netutil.py", line 433, in resolve
    for fam, _, _, _, address in await asyncio.get_running_loop().getaddrinfo(
  File "/usr/lib/python3.9/asyncio/base_events.py", line 856, in getaddrinfo
    return await self.run_in_executor(
  File "/usr/lib/python3.9/concurrent/futures/thread.py", line 52, in run
    result = self.fn(*self.args, **self.kwargs)
  File "/usr/lib/python3.9/socket.py", line 953, in getaddrinfo
    for res in _socket.getaddrinfo(host, port, family, type, proto, flags):
socket.gaierror: [Errno -3] Temporary failure in name resolution
2024-11-23 02:51:04,303 [ioloop.py:_run_callback()] - Exception in callback functools.partial(<function _HTTPConnection.__init__.<locals>.<lambda> at 0xf29d3bb0>, <Task finished name='Task-2517749' coro=<_HTTPConnection.run() done, defined at /home/pi/moonraker-env/lib/python3.9/site-packages/tornado/simple_httpclient.py:290> exception=gaierror(-3, 'Temporary failure in name resolution')>)
Traceback (most recent call last):
  File "/home/pi/moonraker-env/lib/python3.9/site-packages/tornado/ioloop.py", line 750, in _run_callback
    ret = callback()
  File "/home/pi/moonraker-env/lib/python3.9/site-packages/tornado/simple_httpclient.py", line 287, in <lambda>
    gen.convert_yielded(self.run()), lambda f: f.result()
  File "/home/pi/moonraker-env/lib/python3.9/site-packages/tornado/simple_httpclient.py", line 340, in run
    stream = await self.tcp_client.connect(
  File "/home/pi/moonraker-env/lib/python3.9/site-packages/tornado/tcpclient.py", line 269, in connect
    addrinfo = await self.resolver.resolve(host, port, af)
  File "/home/pi/moonraker-env/lib/python3.9/site-packages/tornado/netutil.py", line 433, in resolve
    for fam, _, _, _, address in await asyncio.get_running_loop().getaddrinfo(
  File "/usr/lib/python3.9/asyncio/base_events.py", line 856, in getaddrinfo
    return await self.run_in_executor(
  File "/usr/lib/python3.9/concurrent/futures/thread.py", line 52, in run
    result = self.fn(*self.args, **self.kwargs)
  File "/usr/lib/python3.9/socket.py", line 953, in getaddrinfo
    for res in _socket.getaddrinfo(host, port, family, type, proto, flags):
socket.gaierror: [Errno -3] Temporary failure in name resolution
2024-11-23 02:51:12,878 [announcements.py:_fetch_moonlight()] - Failed to update subscription 'klipper': Timeout while connecting
2024-11-23 02:51:13,998 [ioloop.py:_run_callback()] - Exception in callback functools.partial(<function _HTTPConnection.__init__.<locals>.<lambda> at 0xf3c00e38>, <Task finished name='Task-2517910' coro=<_HTTPConnection.run() done, defined at /home/pi/moonraker-env/lib/python3.9/site-packages/tornado/simple_httpclient.py:290> exception=gaierror(-3, 'Temporary failure in name resolution')>)
Traceback (most recent call last):
  File "/home/pi/moonraker-env/lib/python3.9/site-packages/tornado/ioloop.py", line 750, in _run_callback
    ret = callback()
  File "/home/pi/moonraker-env/lib/python3.9/site-packages/tornado/simple_httpclient.py", line 287, in <lambda>
    gen.convert_yielded(self.run()), lambda f: f.result()
  File "/home/pi/moonraker-env/lib/python3.9/site-packages/tornado/simple_httpclient.py", line 340, in run
    stream = await self.tcp_client.connect(
  File "/home/pi/moonraker-env/lib/python3.9/site-packages/tornado/tcpclient.py", line 269, in connect
    addrinfo = await self.resolver.resolve(host, port, af)
  File "/home/pi/moonraker-env/lib/python3.9/site-packages/tornado/netutil.py", line 433, in resolve
    for fam, _, _, _, address in await asyncio.get_running_loop().getaddrinfo(
  File "/usr/lib/python3.9/asyncio/base_events.py", line 856, in getaddrinfo
    return await self.run_in_executor(
  File "/usr/lib/python3.9/concurrent/futures/thread.py", line 52, in run
    result = self.fn(*self.args, **self.kwargs)
  File "/usr/lib/python3.9/socket.py", line 953, in getaddrinfo
    for res in _socket.getaddrinfo(host, port, family, type, proto, flags):
socket.gaierror: [Errno -3] Temporary failure in name resolution
2024-11-23 02:51:23,215 [ioloop.py:_run_callback()] - Exception in callback functools.partial(<function _HTTPConnection.__init__.<locals>.<lambda> at 0xf3b42658>, <Task finished name='Task-2518074' coro=<_HTTPConnection.run() done, defined at /home/pi/moonraker-env/lib/python3.9/site-packages/tornado/simple_httpclient.py:290> exception=gaierror(-3, 'Temporary failure in name resolution')>)
Traceback (most recent call last):
  File "/home/pi/moonraker-env/lib/python3.9/site-packages/tornado/ioloop.py", line 750, in _run_callback
    ret = callback()
  File "/home/pi/moonraker-env/lib/python3.9/site-packages/tornado/simple_httpclient.py", line 287, in <lambda>
    gen.convert_yielded(self.run()), lambda f: f.result()
  File "/home/pi/moonraker-env/lib/python3.9/site-packages/tornado/simple_httpclient.py", line 340, in run
    stream = await self.tcp_client.connect(
  File "/home/pi/moonraker-env/lib/python3.9/site-packages/tornado/tcpclient.py", line 269, in connect
    addrinfo = await self.resolver.resolve(host, port, af)
  File "/home/pi/moonraker-env/lib/python3.9/site-packages/tornado/netutil.py", line 433, in resolve
    for fam, _, _, _, address in await asyncio.get_running_loop().getaddrinfo(
  File "/usr/lib/python3.9/asyncio/base_events.py", line 856, in getaddrinfo
    return await self.run_in_executor(
  File "/usr/lib/python3.9/concurrent/futures/thread.py", line 52, in run
    result = self.fn(*self.args, **self.kwargs)
  File "/usr/lib/python3.9/socket.py", line 953, in getaddrinfo
    for res in _socket.getaddrinfo(host, port, family, type, proto, flags):
socket.gaierror: [Errno -3] Temporary failure in name resolution
2024-11-23 02:51:32,431 [ioloop.py:_run_callback()] - Exception in callback functools.partial(<function _HTTPConnection.__init__.<locals>.<lambda> at 0xf3b97808>, <Task finished name='Task-2518230' coro=<_HTTPConnection.run() done, defined at /home/pi/moonraker-env/lib/python3.9/site-packages/tornado/simple_httpclient.py:290> exception=gaierror(-3, 'Temporary failure in name resolution')>)
Traceback (most recent call last):
  File "/home/pi/moonraker-env/lib/python3.9/site-packages/tornado/ioloop.py", line 750, in _run_callback
    ret = callback()
  File "/home/pi/moonraker-env/lib/python3.9/site-packages/tornado/simple_httpclient.py", line 287, in <lambda>
    gen.convert_yielded(self.run()), lambda f: f.result()
  File "/home/pi/moonraker-env/lib/python3.9/site-packages/tornado/simple_httpclient.py", line 340, in run
    stream = await self.tcp_client.connect(
  File "/home/pi/moonraker-env/lib/python3.9/site-packages/tornado/tcpclient.py", line 269, in connect
    addrinfo = await self.resolver.resolve(host, port, af)
  File "/home/pi/moonraker-env/lib/python3.9/site-packages/tornado/netutil.py", line 433, in resolve
    for fam, _, _, _, address in await asyncio.get_running_loop().getaddrinfo(
  File "/usr/lib/python3.9/asyncio/base_events.py", line 856, in getaddrinfo
    return await self.run_in_executor(
  File "/usr/lib/python3.9/concurrent/futures/thread.py", line 52, in run
    result = self.fn(*self.args, **self.kwargs)
  File "/usr/lib/python3.9/socket.py", line 953, in getaddrinfo
    for res in _socket.getaddrinfo(host, port, family, type, proto, flags):
socket.gaierror: [Errno -3] Temporary failure in name resolution
2024-11-23 02:51:35,503 [announcements.py:_fetch_moonlight()] - Failed to update subscription 'moonraker-telegram-bot': [Errno -3] Temporary failure in name resolution
2024-11-23 03:01:10,574 [machine.py:_find_public_ip()] - Detected Local IP: 169.254.85.87
2024-11-23 03:02:20,664 [machine.py:_find_public_ip()] - Detected Local IP: 192.168.1.224
2024-11-23 03:02:20,670 [webcam.py:_set_default_host_ip()] - Default public webcam address set: http://192.168.1.224
2024-11-23 03:02:37,731 [application.py:log_request()] - 101 GET /websocket?token=3IYZQUMEGECSYNA55TFPW7LD4CB5K2XK (192.168.1.224) [_API_KEY_USER_] 1.91ms
2024-11-23 03:02:37,731 [websockets.py:open()] - Websocket Opened: ID: 4089015240, Proxied: False, User Agent: , Host Name: 192.168.1.224
2024-11-23 03:02:37,950 [application.py:log_request()] - 404 GET /server/files/metadata?filename=Hogwarts_-_part_1.v2%20-%20Copy.gcode (192.168.1.224) [_API_KEY_USER_] 2.14ms
2024-11-23 03:04:00,793 [machine.py:_find_public_ip()] - Detected Local IP: 192.168.1.224
2024-11-23 03:04:10,781 [machine.py:_find_public_ip()] - Detected Local IP: 192.168.1.224
2024-11-23 03:04:20,809 [machine.py:_find_public_ip()] - Detected Local IP: 192.168.1.224
2024-11-23 03:04:30,803 [machine.py:_find_public_ip()] - Detected Local IP: 192.168.1.224
